Workbook

Sheet 0.0 Leia-me
B2: Planilha Mestre de Importação
B3: Use como base para o script de ETL de carga do sistema principal.
B6: COMO USAR
B7: 1. Preencha as abas na ordem em que aparecem (o número no nome da aba é a ordem de carga).
B8: 2. Cada aba tem uma linha de exemplo (fundo amarelo, itálico) na linha 2 — apague-a ou sobrescreva-a.
B9: 3. Campos com * no cabeçalho são obrigatórios. Uma célula obrigatória vazia em uma linha já iniciada fica destacada em vermelho.
B10: 4. Sempre que possível, preencha usando os menus suspensos (setas nas células) — eles evitam erros de digitação.
B11: 5. Campos que fazem referência a outro cadastro (ex.: Curso de um Currículo) mostram uma lista com o NOME já cadastrado na aba correspondente — não digite códigos manualmente.
B12: 6. Não edite as colunas cinzas ocultas à direita de cada tabela — elas calculam automaticamente o valor técnico que o sistema espera, a partir do que você preencheu. Seu script de ETL deve ler apenas essas colunas (o cabeçalho de cada uma já é o nome técnico exigido pela documentação de importação).
B13: 7. A aba 'Parâmetros' guarda configurações da unidade (sigla, uso de GPA/NPJ) usadas como referência ao preencher outras abas.
B14: 8. Blocos 5 (Subgrupos) e 6 (Manutenção) são opcionais / usados depois da carga inicial — só preencha se precisar.
B16: ORDEM DOS BLOCOS (é também a ordem que o script deve processar)
... B27: Roxo — Matrículas | Cinza — Subgrupos (opcional) | Vermelho — Manutenção

Sheet 0.1 Parametros
A1: Parâmetro | B1: Valor | C1: Observação
A2: Sigla da Unidade | B2: UNIG
A3: Nome da Unidade | B3: Nova Iguaçu
A4: Integra com GPA? | B4: Não
A5: Integra com NPJ? | B5: Não

Sheet 1.1 Modalidades
A1: Nome * | B1: Código * | C1: Tipo de Modalidade * | E1: name | F1: externalId | G1: teachingModalityTypeId
A2: Presencial | B2: MOD-001 | C2: PRESENCIAL | E2: =IF(A2="","",A2) -> Presencial | F2: =IF(B2="","",B2) -> MOD-001 | G2: =IFERROR(INDEX(Listas!$B$2:$B$4,MATCH(C2,Listas!$A$2:$A$4,0)),"") -> face_to_face
E3: =IF(A3="","",A3) | F3: =IF(B3="","",B3) | G3: =IFERROR(INDEX(Listas!$B$2:$B$4,MATCH(C3,Listas!$A$2:$A$4,0)),"")
E4: =IF(A4="","",A4) | F4: =IF(B4="","",B4) | G4: =IFERROR(INDEX(Listas!$B$2:$B$4,MATCH(C4,Listas!$A$2:$A$4,0)),"")
E5: =IF(A5="","",A5) | F5: =IF(B5="","",B5) | G5: =IFERROR(INDEX(Listas!$B$2:$B$4,MATCH(C5,Listas!$A$2:$A$4,0)),"")
E6: =IF(A6="","",A6) | F6: =IF(B6="","",B6) | G6: =IFERROR(INDEX(Listas!$B$2:$B$4,MATCH(C6,Listas!$A$2:$A$4,0)),"")
E7: =IF(A7="","",A7) | F7: =IF(B7="","",B7) | G7: =IFERROR(INDEX(Listas!$B$2:$B$4,MATCH(C7,Listas!$A$2:$A$4,0)),"")
E8: =IF(A8="","",A8) | F8: =IF(B8="","",B8) | G8: =IFERROR(INDEX(Listas!$B$2:$B$4,MATCH(C8,Listas!$A$2:$A$4,0)),"")
E9: =IF(A9="","",A9) | F9: =IF(B9="","",B9) | G9: =IFERROR(INDEX(Listas!$B$2:$B$4,MATCH(C9,Listas!$A$2:$A$4,0)),"")
E10: =IF(A10="","",A10) | F10: =IF(B10="","",B10) | G10: =IFERROR(INDEX(Listas!$B$2:$B$4,MATCH(C10,Listas!$A$2:$A$4,0)),"")
E11: =IF(A11="","",A11) | F11: =IF(B11="","",B11) | G11: =IFERROR(INDEX(Listas!$B$2:$B$4,MATCH(C11,Listas!$A$2:$A$4,0)),"")
E12: =IF(A12="","",A12) | F12: =IF(B12="","",B12) | G12: =IFERROR(INDEX(Listas!$B$2:$B$4,MATCH(C12,Listas!$A$2:$A$4,0)),"")
E13: =IF(A13="","",A13) | F13: =IF(B13="","",B13) | G13: =IFERROR(INDEX(Listas!$B$2:$B$4,MATCH(C13,Listas!$A$2:$A$4,0)),"")
E14: =IF(A14="","",A14) | F14: =IF(B14="","",B14) | G14: =IFERROR(INDEX(Listas!$B$2:$B$4,MATCH(C14,Listas!$A$2:$A$4,0)),"")
... E61: =IF(A61="","",A61) | F61: =IF(B61="","",B61) | G61: =IFERROR(INDEX(Listas!$B$2:$B$4,MATCH(C61,Listas!$A$2:$A$4,0)),"")

Sheet 1.2 Niveis Ensino
A1: Nome * | B1: Código * | C1: Tipo de Nível * | E1: name | F1: externalId | G1: educationLevelTypeId
A2: Graduação | B2: LEV-001 | C2: GRADUACAO | E2: =IF(A2="","",A2) -> Graduação | F2: =IF(B2="","",B2) -> LEV-001 | G2: =IFERROR(INDEX(Listas!$E$2:$E$5,MATCH(C2,Listas!$D$2:$D$5,0)),"") -> undergraduate
E3: =IF(A3="","",A3) | F3: =IF(B3="","",B3) | G3: =IFERROR(INDEX(Listas!$E$2:$E$5,MATCH(C3,Listas!$D$2:$D$5,0)),"")
E4: =IF(A4="","",A4) | F4: =IF(B4="","",B4) | G4: =IFERROR(INDEX(Listas!$E$2:$E$5,MATCH(C4,Listas!$D$2:$D$5,0)),"")
E5: =IF(A5="","",A5) | F5: =IF(B5="","",B5) | G5: =IFERROR(INDEX(Listas!$E$2:$E$5,MATCH(C5,Listas!$D$2:$D$5,0)),"")
E6: =IF(A6="","",A6) | F6: =IF(B6="","",B6) | G6: =IFERROR(INDEX(Listas!$E$2:$E$5,MATCH(C6,Listas!$D$2:$D$5,0)),"")
E7: =IF(A7="","",A7) | F7: =IF(B7="","",B7) | G7: =IFERROR(INDEX(Listas!$E$2:$E$5,MATCH(C7,Listas!$D$2:$D$5,0)),"")
E8: =IF(A8="","",A8) | F8: =IF(B8="","",B8) | G8: =IFERROR(INDEX(Listas!$E$2:$E$5,MATCH(C8,Listas!$D$2:$D$5,0)),"")
E9: =IF(A9="","",A9) | F9: =IF(B9="","",B9) | G9: =IFERROR(INDEX(Listas!$E$2:$E$5,MATCH(C9,Listas!$D$2:$D$5,0)),"")
E10: =IF(A10="","",A10) | F10: =IF(B10="","",B10) | G10: =IFERROR(INDEX(Listas!$E$2:$E$5,MATCH(C10,Listas!$D$2:$D$5,0)),"")
E11: =IF(A11="","",A11) | F11: =IF(B11="","",B11) | G11: =IFERROR(INDEX(Listas!$E$2:$E$5,MATCH(C11,Listas!$D$2:$D$5,0)),"")
E12: =IF(A12="","",A12) | F12: =IF(B12="","",B12) | G12: =IFERROR(INDEX(Listas!$E$2:$E$5,MATCH(C12,Listas!$D$2:$D$5,0)),"")
E13: =IF(A13="","",A13) | F13: =IF(B13="","",B13) | G13: =IFERROR(INDEX(Listas!$E$2:$E$5,MATCH(C13,Listas!$D$2:$D$5,0)),"")
E14: =IF(A14="","",A14) | F14: =IF(B14="","",B14) | G14: =IFERROR(INDEX(Listas!$E$2:$E$5,MATCH(C14,Listas!$D$2:$D$5,0)),"")
... E61: =IF(A61="","",A61) | F61: =IF(B61="","",B61) | G61: =IFERROR(INDEX(Listas!$E$2:$E$5,MATCH(C61,Listas!$D$2:$D$5,0)),"")

Sheet 1.3 Categorias Disc
A1: Nome * | B1: Código * | C1: Tipo de Categoria * | D1: Ativa? * | F1: name | G1: externalId | H1: subjectCategoryTypeId | I1: isActive
A2: Disciplina Normal | B2: CAT-001 | C2: ESTAGIO | D2: Não | F2: =IF(A2="","",A2) -> Disciplina Normal | G2: =IF(B2="","",B2) -> CAT-001 | H2: =IFERROR(INDEX(Listas!$K$2:$K$13,MATCH(C2,Listas!$J$2:$J$13,0)),"") -> internship | I2: =IF(D2="Sim","true",IF(D2="Não","false","")) -> false
F3: =IF(A3="","",A3) | G3: =IF(B3="","",B3) | H3: =IFERROR(INDEX(Listas!$K$2:$K$13,MATCH(C3,Listas!$J$2:$J$13,0)),"") | I3: =IF(D3="Sim","true",IF(D3="Não","false",""))
F4: =IF(A4="","",A4) | G4: =IF(B4="","",B4) | H4: =IFERROR(INDEX(Listas!$K$2:$K$13,MATCH(C4,Listas!$J$2:$J$13,0)),"") | I4: =IF(D4="Sim","true",IF(D4="Não","false",""))
F5: =IF(A5="","",A5) | G5: =IF(B5="","",B5) | H5: =IFERROR(INDEX(Listas!$K$2:$K$13,MATCH(C5,Listas!$J$2:$J$13,0)),"") | I5: =IF(D5="Sim","true",IF(D5="Não","false",""))
F6: =IF(A6="","",A6) | G6: =IF(B6="","",B6) | H6: =IFERROR(INDEX(Listas!$K$2:$K$13,MATCH(C6,Listas!$J$2:$J$13,0)),"") | I6: =IF(D6="Sim","true",IF(D6="Não","false",""))
F7: =IF(A7="","",A7) | G7: =IF(B7="","",B7) | H7: =IFERROR(INDEX(Listas!$K$2:$K$13,MATCH(C7,Listas!$J$2:$J$13,0)),"") | I7: =IF(D7="Sim","true",IF(D7="Não","false",""))
F8: =IF(A8="","",A8) | G8: =IF(B8="","",B8) | H8: =IFERROR(INDEX(Listas!$K$2:$K$13,MATCH(C8,Listas!$J$2:$J$13,0)),"") | I8: =IF(D8="Sim","true",IF(D8="Não","false",""))
F9: =IF(A9="","",A9) | G9: =IF(B9="","",B9) | H9: =IFERROR(INDEX(Listas!$K$2:$K$13,MATCH(C9,Listas!$J$2:$J$13,0)),"") | I9: =IF(D9="Sim","true",IF(D9="Não","false",""))
F10: =IF(A10="","",A10) | G10: =IF(B10="","",B10) | H10: =IFERROR(INDEX(Listas!$K$2:$K$13,MATCH(C10,Listas!$J$2:$J$13,0)),"") | I10: =IF(D10="Sim","true",IF(D10="Não","false",""))
F11: =IF(A11="","",A11) | G11: =IF(B11="","",B11) | H11: =IFERROR(INDEX(Listas!$K$2:$K$13,MATCH(C11,Listas!$J$2:$J$13,0)),"") | I11: =IF(D11="Sim","true",IF(D11="Não","false",""))
F12: =IF(A12="","",A12) | G12: =IF(B12="","",B12) | H12: =IFERROR(INDEX(Listas!$K$2:$K$13,MATCH(C12,Listas!$J$2:$J$13,0)),"") | I12: =IF(D12="Sim","true",IF(D12="Não","false",""))
F13: =IF(A13="","",A13) | G13: =IF(B13="","",B13) | H13: =IFERROR(INDEX(Listas!$K$2:$K$13,MATCH(C13,Listas!$J$2:$J$13,0)),"") | I13: =IF(D13="Sim","true",IF(D13="Não","false",""))
F14: =IF(A14="","",A14) | G14: =IF(B14="","",B14) | H14: =IFERROR(INDEX(Listas!$K$2:$K$13,MATCH(C14,Listas!$J$2:$J$13,0)),"") | I14: =IF(D14="Sim","true",IF(D14="Não","false",""))
... F61: =IF(A61="","",A61) | G61: =IF(B61="","",B61) | H61: =IFERROR(INDEX(Listas!$K$2:$K$13,MATCH(C61,Listas!$J$2:$J$13,0)),"") | I61: =IF(D61="Sim","true",IF(D61="Não","false",""))

Sheet 1.4 Turnos
A1: Nome * | B1: Código * | D1: name | E1: externalId
A2: Manhã | B2: TUR-001 | D2: =IF(A2="","",A2) -> Manhã | E2: =IF(B2="","",B2) -> TUR-001
D3: =IF(A3="","",A3) | E3: =IF(B3="","",B3)
D4: =IF(A4="","",A4) | E4: =IF(B4="","",B4)
D5: =IF(A5="","",A5) | E5: =IF(B5="","",B5)
D6: =IF(A6="","",A6) | E6: =IF(B6="","",B6)
D7: =IF(A7="","",A7) | E7: =IF(B7="","",B7)
D8: =IF(A8="","",A8) | E8: =IF(B8="","",B8)
D9: =IF(A9="","",A9) | E9: =IF(B9="","",B9)
D10: =IF(A10="","",A10) | E10: =IF(B10="","",B10)
D11: =IF(A11="","",A11) | E11: =IF(B11="","",B11)
D12: =IF(A12="","",A12) | E12: =IF(B12="","",B12)
D13: =IF(A13="","",A13) | E13: =IF(B13="","",B13)
D14: =IF(A14="","",A14) | E14: =IF(B14="","",B14)
... D61: =IF(A61="","",A61) | E61: =IF(B61="","",B61)

Sheet 1.5 Campus
A1: Nome * | B1: Código * | C1: CNPJ | D1: Ativo? * | F1: name | G1: externalId | H1: cnpj | I1: isActive
A2: Campus Nova Iguaçu | B2: CAMP-001 | C2: 12345678000199 | D2: Sim | F2: =IF(A2="","",A2) -> Campus Nova Iguaçu | G2: =IF(B2="","",B2) -> CAMP-001 | H2: =IF(C2="","",C2) -> 12345678000199 | I2: =IF(D2="Sim","true",IF(D2="Não","false","")) -> true
F3: =IF(A3="","",A3) | G3: =IF(B3="","",B3) | H3: =IF(C3="","",C3) | I3: =IF(D3="Sim","true",IF(D3="Não","false",""))
F4: =IF(A4="","",A4) | G4: =IF(B4="","",B4) | H4: =IF(C4="","",C4) | I4: =IF(D4="Sim","true",IF(D4="Não","false",""))
F5: =IF(A5="","",A5) | G5: =IF(B5="","",B5) | H5: =IF(C5="","",C5) | I5: =IF(D5="Sim","true",IF(D5="Não","false",""))
F6: =IF(A6="","",A6) | G6: =IF(B6="","",B6) | H6: =IF(C6="","",C6) | I6: =IF(D6="Sim","true",IF(D6="Não","false",""))
F7: =IF(A7="","",A7) | G7: =IF(B7="","",B7) | H7: =IF(C7="","",C7) | I7: =IF(D7="Sim","true",IF(D7="Não","false",""))
F8: =IF(A8="","",A8) | G8: =IF(B8="","",B8) | H8: =IF(C8="","",C8) | I8: =IF(D8="Sim","true",IF(D8="Não","false",""))
F9: =IF(A9="","",A9) | G9: =IF(B9="","",B9) | H9: =IF(C9="","",C9) | I9: =IF(D9="Sim","true",IF(D9="Não","false",""))
F10: =IF(A10="","",A10) | G10: =IF(B10="","",B10) | H10: =IF(C10="","",C10) | I10: =IF(D10="Sim","true",IF(D10="Não","false",""))
F11: =IF(A11="","",A11) | G11: =IF(B11="","",B11) | H11: =IF(C11="","",C11) | I11: =IF(D11="Sim","true",IF(D11="Não","false",""))
F12: =IF(A12="","",A12) | G12: =IF(B12="","",B12) | H12: =IF(C12="","",C12) | I12: =IF(D12="Sim","true",IF(D12="Não","false",""))
F13: =IF(A13="","",A13) | G13: =IF(B13="","",B13) | H13: =IF(C13="","",C13) | I13: =IF(D13="Sim","true",IF(D13="Não","false",""))
F14: =IF(A14="","",A14) | G14: =IF(B14="","",B14) | H14: =IF(C14="","",C14) | I14: =IF(D14="Sim","true",IF(D14="Não","false",""))
... F61: =IF(A61="","",A61) | G61: =IF(B61="","",B61) | H61: =IF(C61="","",C61) | I61: =IF(D61="Sim","true",IF(D61="Não","false",""))

Sheet 1.6 Polos
A1: Nome * | B1: Código * | C1: Ativo? * | E1: name | F1: externalId | G1: isActive
A2: Polo Nova Iguaçu | B2: POL-001 | C2: Sim | E2: =IF(A2="","",A2) -> Polo Nova Iguaçu | F2: =IF(B2="","",B2) -> POL-001 | G2: =IF(C2="Sim","true",IF(C2="Não","false","")) -> true
E3: =IF(A3="","",A3) | F3: =IF(B3="","",B3) | G3: =IF(C3="Sim","true",IF(C3="Não","false",""))
E4: =IF(A4="","",A4) | F4: =IF(B4="","",B4) | G4: =IF(C4="Sim","true",IF(C4="Não","false",""))
E5: =IF(A5="","",A5) | F5: =IF(B5="","",B5) | G5: =IF(C5="Sim","true",IF(C5="Não","false",""))
E6: =IF(A6="","",A6) | F6: =IF(B6="","",B6) | G6: =IF(C6="Sim","true",IF(C6="Não","false",""))
E7: =IF(A7="","",A7) | F7: =IF(B7="","",B7) | G7: =IF(C7="Sim","true",IF(C7="Não","false",""))
E8: =IF(A8="","",A8) | F8: =IF(B8="","",B8) | G8: =IF(C8="Sim","true",IF(C8="Não","false",""))
E9: =IF(A9="","",A9) | F9: =IF(B9="","",B9) | G9: =IF(C9="Sim","true",IF(C9="Não","false",""))
E10: =IF(A10="","",A10) | F10: =IF(B10="","",B10) | G10: =IF(C10="Sim","true",IF(C10="Não","false",""))
E11: =IF(A11="","",A11) | F11: =IF(B11="","",B11) | G11: =IF(C11="Sim","true",IF(C11="Não","false",""))
E12: =IF(A12="","",A12) | F12: =IF(B12="","",B12) | G12: =IF(C12="Sim","true",IF(C12="Não","false",""))
E13: =IF(A13="","",A13) | F13: =IF(B13="","",B13) | G13: =IF(C13="Sim","true",IF(C13="Não","false",""))
E14: =IF(A14="","",A14) | F14: =IF(B14="","",B14) | G14: =IF(C14="Sim","true",IF(C14="Não","false",""))
... E61: =IF(A61="","",A61) | F61: =IF(B61="","",B61) | G61: =IF(C61="Sim","true",IF(C61="Não","false",""))

Sheet 1.7 Sit Matricula
A1: Nome * | B1: Código * | C1: Tipo * | E1: name | F1: externalId | G1: enrollmentStatusTypeId
A2: Ativo | B2: STATUS-001 | C2: Ativo | E2: =IF(A2="","",A2) -> Ativo | F2: =IF(B2="","",B2) -> STATUS-001 | G2: =IFERROR(INDEX(Listas!$Q$2:$Q$6,MATCH(C2,Listas!$P$2:$P$6,0)),"") -> active
E3: =IF(A3="","",A3) | F3: =IF(B3="","",B3) | G3: =IFERROR(INDEX(Listas!$Q$2:$Q$6,MATCH(C3,Listas!$P$2:$P$6,0)),"")
E4: =IF(A4="","",A4) | F4: =IF(B4="","",B4) | G4: =IFERROR(INDEX(Listas!$Q$2:$Q$6,MATCH(C4,Listas!$P$2:$P$6,0)),"")
E5: =IF(A5="","",A5) | F5: =IF(B5="","",B5) | G5: =IFERROR(INDEX(Listas!$Q$2:$Q$6,MATCH(C5,Listas!$P$2:$P$6,0)),"")
E6: =IF(A6="","",A6) | F6: =IF(B6="","",B6) | G6: =IFERROR(INDEX(Listas!$Q$2:$Q$6,MATCH(C6,Listas!$P$2:$P$6,0)),"")
E7: =IF(A7="","",A7) | F7: =IF(B7="","",B7) | G7: =IFERROR(INDEX(Listas!$Q$2:$Q$6,MATCH(C7,Listas!$P$2:$P$6,0)),"")
E8: =IF(A8="","",A8) | F8: =IF(B8="","",B8) | G8: =IFERROR(INDEX(Listas!$Q$2:$Q$6,MATCH(C8,Listas!$P$2:$P$6,0)),"")
E9: =IF(A9="","",A9) | F9: =IF(B9="","",B9) | G9: =IFERROR(INDEX(Listas!$Q$2:$Q$6,MATCH(C9,Listas!$P$2:$P$6,0)),"")
E10: =IF(A10="","",A10) | F10: =IF(B10="","",B10) | G10: =IFERROR(INDEX(Listas!$Q$2:$Q$6,MATCH(C10,Listas!$P$2:$P$6,0)),"")
E11: =IF(A11="","",A11) | F11: =IF(B11="","",B11) | G11: =IFERROR(INDEX(Listas!$Q$2:$Q$6,MATCH(C11,Listas!$P$2:$P$6,0)),"")
E12: =IF(A12="","",A12) | F12: =IF(B12="","",B12) | G12: =IFERROR(INDEX(Listas!$Q$2:$Q$6,MATCH(C12,Listas!$P$2:$P$6,0)),"")
E13: =IF(A13="","",A13) | F13: =IF(B13="","",B13) | G13: =IFERROR(INDEX(Listas!$Q$2:$Q$6,MATCH(C13,Listas!$P$2:$P$6,0)),"")
E14: =IF(A14="","",A14) | F14: =IF(B14="","",B14) | G14: =IFERROR(INDEX(Listas!$Q$2:$Q$6,MATCH(C14,Listas!$P$2:$P$6,0)),"")
... E61: =IF(A61="","",A61) | F61: =IF(B61="","",B61) | G61: =IFERROR(INDEX(Listas!$Q$2:$Q$6,MATCH(C61,Listas!$P$2:$P$6,0)),"")

Sheet 1.8 Sit Enturmacao
A1: Nome * | B1: Código * | C1: Tipo * | E1: name | F1: externalId | G1: enrollmentClassSubjectStatusTypeId
A2: Ativo | B2: STATUSENT-001 | C2: Ativo | E2: =IF(A2="","",A2) -> Ativo | F2: =IF(B2="","",B2) -> STATUSENT-001 | G2: =IFERROR(INDEX(Listas!$T$2:$T$4,MATCH(C2,Listas!$S$2:$S$4,0)),"") -> active
E3: =IF(A3="","",A3) | F3: =IF(B3="","",B3) | G3: =IFERROR(INDEX(Listas!$T$2:$T$4,MATCH(C3,Listas!$S$2:$S$4,0)),"")
E4: =IF(A4="","",A4) | F4: =IF(B4="","",B4) | G4: =IFERROR(INDEX(Listas!$T$2:$T$4,MATCH(C4,Listas!$S$2:$S$4,0)),"")
E5: =IF(A5="","",A5) | F5: =IF(B5="","",B5) | G5: =IFERROR(INDEX(Listas!$T$2:$T$4,MATCH(C5,Listas!$S$2:$S$4,0)),"")
E6: =IF(A6="","",A6) | F6: =IF(B6="","",B6) | G6: =IFERROR(INDEX(Listas!$T$2:$T$4,MATCH(C6,Listas!$S$2:$S$4,0)),"")
E7: =IF(A7="","",A7) | F7: =IF(B7="","",B7) | G7: =IFERROR(INDEX(Listas!$T$2:$T$4,MATCH(C7,Listas!$S$2:$S$4,0)),"")
E8: =IF(A8="","",A8) | F8: =IF(B8="","",B8) | G8: =IFERROR(INDEX(Listas!$T$2:$T$4,MATCH(C8,Listas!$S$2:$S$4,0)),"")
E9: =IF(A9="","",A9) | F9: =IF(B9="","",B9) | G9: =IFERROR(INDEX(Listas!$T$2:$T$4,MATCH(C9,Listas!$S$2:$S$4,0)),"")
E10: =IF(A10="","",A10) | F10: =IF(B10="","",B10) | G10: =IFERROR(INDEX(Listas!$T$2:$T$4,MATCH(C10,Listas!$S$2:$S$4,0)),"")
E11: =IF(A11="","",A11) | F11: =IF(B11="","",B11) | G11: =IFERROR(INDEX(Listas!$T$2:$T$4,MATCH(C11,Listas!$S$2:$S$4,0)),"")
E12: =IF(A12="","",A12) | F12: =IF(B12="","",B12) | G12: =IFERROR(INDEX(Listas!$T$2:$T$4,MATCH(C12,Listas!$S$2:$S$4,0)),"")
E13: =IF(A13="","",A13) | F13: =IF(B13="","",B13) | G13: =IFERROR(INDEX(Listas!$T$2:$T$4,MATCH(C13,Listas!$S$2:$S$4,0)),"")
E14: =IF(A14="","",A14) | F14: =IF(B14="","",B14) | G14: =IFERROR(INDEX(Listas!$T$2:$T$4,MATCH(C14,Listas!$S$2:$S$4,0)),"")
... E61: =IF(A61="","",A61) | F61: =IF(B61="","",B61) | G61: =IFERROR(INDEX(Listas!$T$2:$T$4,MATCH(C61,Listas!$S$2:$S$4,0)),"")

Sheet 1.9 Tipos Matricula
A1: Nome * | B1: Código * | D1: name | E1: externalId
A2: Regular | B2: TYPE-001 | D2: =IF(A2="","",A2) -> Regular | E2: =IF(B2="","",B2) -> TYPE-001
D3: =IF(A3="","",A3) | E3: =IF(B3="","",B3)
D4: =IF(A4="","",A4) | E4: =IF(B4="","",B4)
D5: =IF(A5="","",A5) | E5: =IF(B5="","",B5)
D6: =IF(A6="","",A6) | E6: =IF(B6="","",B6)
D7: =IF(A7="","",A7) | E7: =IF(B7="","",B7)
D8: =IF(A8="","",A8) | E8: =IF(B8="","",B8)
D9: =IF(A9="","",A9) | E9: =IF(B9="","",B9)
D10: =IF(A10="","",A10) | E10: =IF(B10="","",B10)
D11: =IF(A11="","",A11) | E11: =IF(B11="","",B11)
D12: =IF(A12="","",A12) | E12: =IF(B12="","",B12)
D13: =IF(A13="","",A13) | E13: =IF(B13="","",B13)
D14: =IF(A14="","",A14) | E14: =IF(B14="","",B14)
... D61: =IF(A61="","",A61) | E61: =IF(B61="","",B61)

Sheet 1.10 Papeis TD
A1: Nome * | B1: Código * | C1: Tipo * | E1: name | F1: externalId | G1: roleType
A2: Professor | B2: ROLE-001 | C2: Professor | E2: =IF(A2="","",A2) -> Professor | F2: =IF(B2="","",B2) -> ROLE-001 | G2: =IFERROR(INDEX(Listas!$W$2:$W$7,MATCH(C2,Listas!$V$2:$V$7,0)),"") -> teacher
E3: =IF(A3="","",A3) | F3: =IF(B3="","",B3) | G3: =IFERROR(INDEX(Listas!$W$2:$W$7,MATCH(C3,Listas!$V$2:$V$7,0)),"")
E4: =IF(A4="","",A4) | F4: =IF(B4="","",B4) | G4: =IFERROR(INDEX(Listas!$W$2:$W$7,MATCH(C4,Listas!$V$2:$V$7,0)),"")
E5: =IF(A5="","",A5) | F5: =IF(B5="","",B5) | G5: =IFERROR(INDEX(Listas!$W$2:$W$7,MATCH(C5,Listas!$V$2:$V$7,0)),"")
E6: =IF(A6="","",A6) | F6: =IF(B6="","",B6) | G6: =IFERROR(INDEX(Listas!$W$2:$W$7,MATCH(C6,Listas!$V$2:$V$7,0)),"")
E7: =IF(A7="","",A7) | F7: =IF(B7="","",B7) | G7: =IFERROR(INDEX(Listas!$W$2:$W$7,MATCH(C7,Listas!$V$2:$V$7,0)),"")
E8: =IF(A8="","",A8) | F8: =IF(B8="","",B8) | G8: =IFERROR(INDEX(Listas!$W$2:$W$7,MATCH(C8,Listas!$V$2:$V$7,0)),"")
E9: =IF(A9="","",A9) | F9: =IF(B9="","",B9) | G9: =IFERROR(INDEX(Listas!$W$2:$W$7,MATCH(C9,Listas!$V$2:$V$7,0)),"")
E10: =IF(A10="","",A10) | F10: =IF(B10="","",B10) | G10: =IFERROR(INDEX(Listas!$W$2:$W$7,MATCH(C10,Listas!$V$2:$V$7,0)),"")
E11: =IF(A11="","",A11) | F11: =IF(B11="","",B11) | G11: =IFERROR(INDEX(Listas!$W$2:$W$7,MATCH(C11,Listas!$V$2:$V$7,0)),"")
E12: =IF(A12="","",A12) | F12: =IF(B12="","",B12) | G12: =IFERROR(INDEX(Listas!$W$2:$W$7,MATCH(C12,Listas!$V$2:$V$7,0)),"")
E13: =IF(A13="","",A13) | F13: =IF(B13="","",B13) | G13: =IFERROR(INDEX(Listas!$W$2:$W$7,MATCH(C13,Listas!$V$2:$V$7,0)),"")
E14: =IF(A14="","",A14) | F14: =IF(B14="","",B14) | G14: =IFERROR(INDEX(Listas!$W$2:$W$7,MATCH(C14,Listas!$V$2:$V$7,0)),"")
... E61: =IF(A61="","",A61) | F61: =IF(B61="","",B61) | G61: =IFERROR(INDEX(Listas!$W$2:$W$7,MATCH(C61,Listas!$V$2:$V$7,0)),"")

Sheet 1.11 Turmas
A1: Nome * | B1: Código * | C1: Ativa? * | E1: name | F1: externalId | G1: isActive
A2: Turma A | B2: TURMA-001 | C2: Sim | E2: =IF(A2="","",A2) -> Turma A | F2: =IF(B2="","",B2) -> TURMA-001 | G2: =IF(C2="Sim","true",IF(C2="Não","false","")) -> true
E3: =IF(A3="","",A3) | F3: =IF(B3="","",B3) | G3: =IF(C3="Sim","true",IF(C3="Não","false",""))
E4: =IF(A4="","",A4) | F4: =IF(B4="","",B4) | G4: =IF(C4="Sim","true",IF(C4="Não","false",""))
E5: =IF(A5="","",A5) | F5: =IF(B5="","",B5) | G5: =IF(C5="Sim","true",IF(C5="Não","false",""))
E6: =IF(A6="","",A6) | F6: =IF(B6="","",B6) | G6: =IF(C6="Sim","true",IF(C6="Não","false",""))
E7: =IF(A7="","",A7) | F7: =IF(B7="","",B7) | G7: =IF(C7="Sim","true",IF(C7="Não","false",""))
E8: =IF(A8="","",A8) | F8: =IF(B8="","",B8) | G8: =IF(C8="Sim","true",IF(C8="Não","false",""))
E9: =IF(A9="","",A9) | F9: =IF(B9="","",B9) | G9: =IF(C9="Sim","true",IF(C9="Não","false",""))
E10: =IF(A10="","",A10) | F10: =IF(B10="","",B10) | G10: =IF(C10="Sim","true",IF(C10="Não","false",""))
E11: =IF(A11="","",A11) | F11: =IF(B11="","",B11) | G11: =IF(C11="Sim","true",IF(C11="Não","false",""))
E12: =IF(A12="","",A12) | F12: =IF(B12="","",B12) | G12: =IF(C12="Sim","true",IF(C12="Não","false",""))
E13: =IF(A13="","",A13) | F13: =IF(B13="","",B13) | G13: =IF(C13="Sim","true",IF(C13="Não","false",""))
E14: =IF(A14="","",A14) | F14: =IF(B14="","",B14) | G14: =IF(C14="Sim","true",IF(C14="Não","false",""))
... E61: =IF(A61="","",A61) | F61: =IF(B61="","",B61) | G61: =IF(C61="Sim","true",IF(C61="Não","false",""))

Sheet 1.12 Pessoas
A1: Nome Completo * | B1: Nome Social | C1: Documento | D1: Tipo de Documento | E1: Passaporte | F1: Código * | G1: CEP | H1: Estado | I1: Cidade | J1: Endereço | K1: Número | L1: Bairro | M1: Complemento | N1: E-mail de Acesso * | O1: Login * | P1: Senha * | Q1: Tags | R1: Ativa? | T1: name | U1: socialName | V1: identityDocument | W1: identityDocumentTypeId | X1: passportNumber | Y1: externalId | Z1: address.zipCode | AA1: address.state | AB1: address.city | AC1: address.address | AD1: address.number | AE1: address.neighborhood | AF1: address.complement | AG1: user.email | AH1: user.username | AI1: user.password | AJ1: tags | AK1: isActive
A2: João da Silva | C2: 12345678900 | D2: CPF | F2: PES-001 | G2: 26000000 | H2: RJ | I2: Nova Iguaçu | J2: Rua Exemplo | K2: 100 | L2: Centro | N2: joao@email.com | O2: joao.silva | P2: Senha@123 | Q2: aluno,graduacao | R2: Sim | T2: =IF(A2="","",A2) -> João da Silva | U2: =IF(B2="","",B2) | V2: =IF(C2="","",C2) -> 12345678900 | W2: =IFERROR(INDEX(Listas!$AC$2:$AC$4,MATCH(D2,Listas!$AB$2:$AB$4,0)),"") -> CPF | X2: =IF(E2="","",E2) | Y2: =IF(F2="","",F2) -> PES-001 | Z2: =IF(G2="","",G2) -> 26000000 | AA2: =IF(H2="","",H2) -> RJ | AB2: =IF(I2="","",I2) -> Nova Iguaçu | AC2: =IF(J2="","",J2) -> Rua Exemplo | AD2: =IF(K2="","",K2) -> 100 | AE2: =IF(L2="","",L2) -> Centro | ... AJ2: =IF(Q2="","",Q2) -> aluno,graduacao | AK2: =IF(R2="Sim","true",IF(R2="Não","false","")) -> true
T3: =IF(A3="","",A3) | U3: =IF(B3="","",B3) | V3: =IF(C3="","",C3) | W3: =IFERROR(INDEX(Listas!$AC$2:$AC$4,MATCH(D3,Listas!$AB$2:$AB$4,0)),"") | X3: =IF(E3="","",E3) | Y3: =IF(F3="","",F3) | Z3: =IF(G3="","",G3) | AA3: =IF(H3="","",H3) | AB3: =IF(I3="","",I3) | AC3: =IF(J3="","",J3) | AD3: =IF(K3="","",K3) | AE3: =IF(L3="","",L3) | ... AJ3: =IF(Q3="","",Q3) | AK3: =IF(R3="Sim","true",IF(R3="Não","false",""))
T4: =IF(A4="","",A4) | U4: =IF(B4="","",B4) | V4: =IF(C4="","",C4) | W4: =IFERROR(INDEX(Listas!$AC$2:$AC$4,MATCH(D4,Listas!$AB$2:$AB$4,0)),"") | X4: =IF(E4="","",E4) | Y4: =IF(F4="","",F4) | Z4: =IF(G4="","",G4) | AA4: =IF(H4="","",H4) | AB4: =IF(I4="","",I4) | AC4: =IF(J4="","",J4) | AD4: =IF(K4="","",K4) | AE4: =IF(L4="","",L4) | ... AJ4: =IF(Q4="","",Q4) | AK4: =IF(R4="Sim","true",IF(R4="Não","false",""))
T5: =IF(A5="","",A5) | U5: =IF(B5="","",B5) | V5: =IF(C5="","",C5) | W5: =IFERROR(INDEX(Listas!$AC$2:$AC$4,MATCH(D5,Listas!$AB$2:$AB$4,0)),"") | X5: =IF(E5="","",E5) | Y5: =IF(F5="","",F5) | Z5: =IF(G5="","",G5) | AA5: =IF(H5="","",H5) | AB5: =IF(I5="","",I5) | AC5: =IF(J5="","",J5) | AD5: =IF(K5="","",K5) | AE5: =IF(L5="","",L5) | ... AJ5: =IF(Q5="","",Q5) | AK5: =IF(R5="Sim","true",IF(R5="Não","false",""))
T6: =IF(A6="","",A6) | U6: =IF(B6="","",B6) | V6: =IF(C6="","",C6) | W6: =IFERROR(INDEX(Listas!$AC$2:$AC$4,MATCH(D6,Listas!$AB$2:$AB$4,0)),"") | X6: =IF(E6="","",E6) | Y6: =IF(F6="","",F6) | Z6: =IF(G6="","",G6) | AA6: =IF(H6="","",H6) | AB6: =IF(I6="","",I6) | AC6: =IF(J6="","",J6) | AD6: =IF(K6="","",K6) | AE6: =IF(L6="","",L6) | ... AJ6: =IF(Q6="","",Q6) | AK6: =IF(R6="Sim","true",IF(R6="Não","false",""))
T7: =IF(A7="","",A7) | U7: =IF(B7="","",B7) | V7: =IF(C7="","",C7) | W7: =IFERROR(INDEX(Listas!$AC$2:$AC$4,MATCH(D7,Listas!$AB$2:$AB$4,0)),"") | X7: =IF(E7="","",E7) | Y7: =IF(F7="","",F7) | Z7: =IF(G7="","",G7) | AA7: =IF(H7="","",H7) | AB7: =IF(I7="","",I7) | AC7: =IF(J7="","",J7) | AD7: =IF(K7="","",K7) | AE7: =IF(L7="","",L7) | ... AJ7: =IF(Q7="","",Q7) | AK7: =IF(R7="Sim","true",IF(R7="Não","false",""))
T8: =IF(A8="","",A8) | U8: =IF(B8="","",B8) | V8: =IF(C8="","",C8) | W8: =IFERROR(INDEX(Listas!$AC$2:$AC$4,MATCH(D8,Listas!$AB$2:$AB$4,0)),"") | X8: =IF(E8="","",E8) | Y8: =IF(F8="","",F8) | Z8: =IF(G8="","",G8) | AA8: =IF(H8="","",H8) | AB8: =IF(I8="","",I8) | AC8: =IF(J8="","",J8) | AD8: =IF(K8="","",K8) | AE8: =IF(L8="","",L8) | ... AJ8: =IF(Q8="","",Q8) | AK8: =IF(R8="Sim","true",IF(R8="Não","false",""))
T9: =IF(A9="","",A9) | U9: =IF(B9="","",B9) | V9: =IF(C9="","",C9) | W9: =IFERROR(INDEX(Listas!$AC$2:$AC$4,MATCH(D9,Listas!$AB$2:$AB$4,0)),"") | X9: =IF(E9="","",E9) | Y9: =IF(F9="","",F9) | Z9: =IF(G9="","",G9) | AA9: =IF(H9="","",H9) | AB9: =IF(I9="","",I9) | AC9: =IF(J9="","",J9) | AD9: =IF(K9="","",K9) | AE9: =IF(L9="","",L9) | ... AJ9: =IF(Q9="","",Q9) | AK9: =IF(R9="Sim","true",IF(R9="Não","false",""))
T10: =IF(A10="","",A10) | U10: =IF(B10="","",B10) | V10: =IF(C10="","",C10) | W10: =IFERROR(INDEX(Listas!$AC$2:$AC$4,MATCH(D10,Listas!$AB$2:$AB$4,0)),"") | X10: =IF(E10="","",E10) | Y10: =IF(F10="","",F10) | Z10: =IF(G10="","",G10) | AA10: =IF(H10="","",H10) | AB10: =IF(I10="","",I10) | AC10: =IF(J10="","",J10) | AD10: =IF(K10="","",K10) | AE10: =IF(L10="","",L10) | ... AJ10: =IF(Q10="","",Q10) | AK10: =IF(R10="Sim","true",IF(R10="Não","false",""))
T11: =IF(A11="","",A11) | U11: =IF(B11="","",B11) | V11: =IF(C11="","",C11) | W11: =IFERROR(INDEX(Listas!$AC$2:$AC$4,MATCH(D11,Listas!$AB$2:$AB$4,0)),"") | X11: =IF(E11="","",E11) | Y11: =IF(F11="","",F11) | Z11: =IF(G11="","",G11) | AA11: =IF(H11="","",H11) | AB11: =IF(I11="","",I11) | AC11: =IF(J11="","",J11) | AD11: =IF(K11="","",K11) | AE11: =IF(L11="","",L11) | ... AJ11: =IF(Q11="","",Q11) | AK11: =IF(R11="Sim","true",IF(R11="Não","false",""))
T12: =IF(A12="","",A12) | U12: =IF(B12="","",B12) | V12: =IF(C12="","",C12) | W12: =IFERROR(INDEX(Listas!$AC$2:$AC$4,MATCH(D12,Listas!$AB$2:$AB$4,0)),"") | X12: =IF(E12="","",E12) | Y12: =IF(F12="","",F12) | Z12: =IF(G12="","",G12) | AA12: =IF(H12="","",H12) | AB12: =IF(I12="","",I12) | AC12: =IF(J12="","",J12) | AD12: =IF(K12="","",K12) | AE12: =IF(L12="","",L12) | ... AJ12: =IF(Q12="","",Q12) | AK12: =IF(R12="Sim","true",IF(R12="Não","false",""))
T13: =IF(A13="","",A13) | U13: =IF(B13="","",B13) | V13: =IF(C13="","",C13) | W13: =IFERROR(INDEX(Listas!$AC$2:$AC$4,MATCH(D13,Listas!$AB$2:$AB$4,0)),"") | X13: =IF(E13="","",E13) | Y13: =IF(F13="","",F13) | Z13: =IF(G13="","",G13) | AA13: =IF(H13="","",H13) | AB13: =IF(I13="","",I13) | AC13: =IF(J13="","",J13) | AD13: =IF(K13="","",K13) | AE13: =IF(L13="","",L13) | ... AJ13: =IF(Q13="","",Q13) | AK13: =IF(R13="Sim","true",IF(R13="Não","false",""))
T14: =IF(A14="","",A14) | U14: =IF(B14="","",B14) | V14: =IF(C14="","",C14) | W14: =IFERROR(INDEX(Listas!$AC$2:$AC$4,MATCH(D14,Listas!$AB$2:$AB$4,0)),"") | X14: =IF(E14="","",E14) | Y14: =IF(F14="","",F14) | Z14: =IF(G14="","",G14) | AA14: =IF(H14="","",H14) | AB14: =IF(I14="","",I14) | AC14: =IF(J14="","",J14) | AD14: =IF(K14="","",K14) | AE14: =IF(L14="","",L14) | ... AJ14: =IF(Q14="","",Q14) | AK14: =IF(R14="Sim","true",IF(R14="Não","false",""))
... T61: =IF(A61="","",A61) | U61: =IF(B61="","",B61) | V61: =IF(C61="","",C61) | W61: =IFERROR(INDEX(Listas!$AC$2:$AC$4,MATCH(D61,Listas!$AB$2:$AB$4,0)),"") | X61: =IF(E61="","",E61) | Y61: =IF(F61="","",F61) | Z61: =IF(G61="","",G61) | AA61: =IF(H61="","",H61) | AB61: =IF(I61="","",I61) | AC61: =IF(J61="","",J61) | AD61: =IF(K61="","",K61) | AE61: =IF(L61="","",L61) | ... AJ61: =IF(Q61="","",Q61) | AK61: =IF(R61="Sim","true",IF(R61="Não","false",""))

Sheet 2.1 Cursos
A1: Nome * | B1: Código * | C1: Ativo? * | D1: Modalidade de Ensino * | E1: Nível de Ensino * | F1: Tipo de Curso | H1: name | I1: externalId | J1: isActive | K1: externalTeachingModalityId | L1: externalEducationLevelId | M1: courseTypeId
A2: Administração | B2: CUR-001 | C2: Sim | D2: Presencial | E2: Graduação | F2: Bacharelado | H2: =IF(A2="","",A2) -> Administração | I2: =IF(B2="","",B2) -> CUR-001 | J2: =IF(C2="Sim","true",IF(C2="Não","false","")) -> true | K2: =IFERROR(INDEX('1.1 Modalidades'!$B$2:$B$61,MATCH(D2,'1.1 Modalidades'!$A$2:$A$61,0)),"") -> MOD-001 | L2: =IFERROR(INDEX('1.2 Niveis Ensino'!$B$2:$B$61,MATCH(E2,'1.2 Niveis Ensino'!$A$2:$A$61,0)),"") -> LEV-001 | M2: =IFERROR(INDEX(Listas!$H$2:$H$4,MATCH(F2,Listas!$G$2:$G$4,0)),"") -> bachelor
H3: =IF(A3="","",A3) | I3: =IF(B3="","",B3) | J3: =IF(C3="Sim","true",IF(C3="Não","false","")) | K3: =IFERROR(INDEX('1.1 Modalidades'!$B$2:$B$61,MATCH(D3,'1.1 Modalidades'!$A$2:$A$61,0)),"") | L3: =IFERROR(INDEX('1.2 Niveis Ensino'!$B$2:$B$61,MATCH(E3,'1.2 Niveis Ensino'!$A$2:$A$61,0)),"") | M3: =IFERROR(INDEX(Listas!$H$2:$H$4,MATCH(F3,Listas!$G$2:$G$4,0)),"")
H4: =IF(A4="","",A4) | I4: =IF(B4="","",B4) | J4: =IF(C4="Sim","true",IF(C4="Não","false","")) | K4: =IFERROR(INDEX('1.1 Modalidades'!$B$2:$B$61,MATCH(D4,'1.1 Modalidades'!$A$2:$A$61,0)),"") | L4: =IFERROR(INDEX('1.2 Niveis Ensino'!$B$2:$B$61,MATCH(E4,'1.2 Niveis Ensino'!$A$2:$A$61,0)),"") | M4: =IFERROR(INDEX(Listas!$H$2:$H$4,MATCH(F4,Listas!$G$2:$G$4,0)),"")
H5: =IF(A5="","",A5) | I5: =IF(B5="","",B5) | J5: =IF(C5="Sim","true",IF(C5="Não","false","")) | K5: =IFERROR(INDEX('1.1 Modalidades'!$B$2:$B$61,MATCH(D5,'1.1 Modalidades'!$A$2:$A$61,0)),"") | L5: =IFERROR(INDEX('1.2 Niveis Ensino'!$B$2:$B$61,MATCH(E5,'1.2 Niveis Ensino'!$A$2:$A$61,0)),"") | M5: =IFERROR(INDEX(Listas!$H$2:$H$4,MATCH(F5,Listas!$G$2:$G$4,0)),"")
H6: =IF(A6="","",A6) | I6: =IF(B6="","",B6) | J6: =IF(C6="Sim","true",IF(C6="Não","false","")) | K6: =IFERROR(INDEX('1.1 Modalidades'!$B$2:$B$61,MATCH(D6,'1.1 Modalidades'!$A$2:$A$61,0)),"") | L6: =IFERROR(INDEX('1.2 Niveis Ensino'!$B$2:$B$61,MATCH(E6,'1.2 Niveis Ensino'!$A$2:$A$61,0)),"") | M6: =IFERROR(INDEX(Listas!$H$2:$H$4,MATCH(F6,Listas!$G$2:$G$4,0)),"")
H7: =IF(A7="","",A7) | I7: =IF(B7="","",B7) | J7: =IF(C7="Sim","true",IF(C7="Não","false","")) | K7: =IFERROR(INDEX('1.1 Modalidades'!$B$2:$B$61,MATCH(D7,'1.1 Modalidades'!$A$2:$A$61,0)),"") | L7: =IFERROR(INDEX('1.2 Niveis Ensino'!$B$2:$B$61,MATCH(E7,'1.2 Niveis Ensino'!$A$2:$A$61,0)),"") | M7: =IFERROR(INDEX(Listas!$H$2:$H$4,MATCH(F7,Listas!$G$2:$G$4,0)),"")
H8: =IF(A8="","",A8) | I8: =IF(B8="","",B8) | J8: =IF(C8="Sim","true",IF(C8="Não","false","")) | K8: =IFERROR(INDEX('1.1 Modalidades'!$B$2:$B$61,MATCH(D8,'1.1 Modalidades'!$A$2:$A$61,0)),"") | L8: =IFERROR(INDEX('1.2 Niveis Ensino'!$B$2:$B$61,MATCH(E8,'1.2 Niveis Ensino'!$A$2:$A$61,0)),"") | M8: =IFERROR(INDEX(Listas!$H$2:$H$4,MATCH(F8,Listas!$G$2:$G$4,0)),"")
H9: =IF(A9="","",A9) | I9: =IF(B9="","",B9) | J9: =IF(C9="Sim","true",IF(C9="Não","false","")) | K9: =IFERROR(INDEX('1.1 Modalidades'!$B$2:$B$61,MATCH(D9,'1.1 Modalidades'!$A$2:$A$61,0)),"") | L9: =IFERROR(INDEX('1.2 Niveis Ensino'!$B$2:$B$61,MATCH(E9,'1.2 Niveis Ensino'!$A$2:$A$61,0)),"") | M9: =IFERROR(INDEX(Listas!$H$2:$H$4,MATCH(F9,Listas!$G$2:$G$4,0)),"")
H10: =IF(A10="","",A10) | I10: =IF(B10="","",B10) | J10: =IF(C10="Sim","true",IF(C10="Não","false","")) | K10: =IFERROR(INDEX('1.1 Modalidades'!$B$2:$B$61,MATCH(D10,'1.1 Modalidades'!$A$2:$A$61,0)),"") | L10: =IFERROR(INDEX('1.2 Niveis Ensino'!$B$2:$B$61,MATCH(E10,'1.2 Niveis Ensino'!$A$2:$A$61,0)),"") | M10: =IFERROR(INDEX(Listas!$H$2:$H$4,MATCH(F10,Listas!$G$2:$G$4,0)),"")
H11: =IF(A11="","",A11) | I11: =IF(B11="","",B11) | J11: =IF(C11="Sim","true",IF(C11="Não","false","")) | K11: =IFERROR(INDEX('1.1 Modalidades'!$B$2:$B$61,MATCH(D11,'1.1 Modalidades'!$A$2:$A$61,0)),"") | L11: =IFERROR(INDEX('1.2 Niveis Ensino'!$B$2:$B$61,MATCH(E11,'1.2 Niveis Ensino'!$A$2:$A$61,0)),"") | M11: =IFERROR(INDEX(Listas!$H$2:$H$4,MATCH(F11,Listas!$G$2:$G$4,0)),"")
H12: =IF(A12="","",A12) | I12: =IF(B12="","",B12) | J12: =IF(C12="Sim","true",IF(C12="Não","false","")) | K12: =IFERROR(INDEX('1.1 Modalidades'!$B$2:$B$61,MATCH(D12,'1.1 Modalidades'!$A$2:$A$61,0)),"") | L12: =IFERROR(INDEX('1.2 Niveis Ensino'!$B$2:$B$61,MATCH(E12,'1.2 Niveis Ensino'!$A$2:$A$61,0)),"") | M12: =IFERROR(INDEX(Listas!$H$2:$H$4,MATCH(F12,Listas!$G$2:$G$4,0)),"")
H13: =IF(A13="","",A13) | I13: =IF(B13="","",B13) | J13: =IF(C13="Sim","true",IF(C13="Não","false","")) | K13: =IFERROR(INDEX('1.1 Modalidades'!$B$2:$B$61,MATCH(D13,'1.1 Modalidades'!$A$2:$A$61,0)),"") | L13: =IFERROR(INDEX('1.2 Niveis Ensino'!$B$2:$B$61,MATCH(E13,'1.2 Niveis Ensino'!$A$2:$A$61,0)),"") | M13: =IFERROR(INDEX(Listas!$H$2:$H$4,MATCH(F13,Listas!$G$2:$G$4,0)),"")
H14: =IF(A14="","",A14) | I14: =IF(B14="","",B14) | J14: =IF(C14="Sim","true",IF(C14="Não","false","")) | K14: =IFERROR(INDEX('1.1 Modalidades'!$B$2:$B$61,MATCH(D14,'1.1 Modalidades'!$A$2:$A$61,0)),"") | L14: =IFERROR(INDEX('1.2 Niveis Ensino'!$B$2:$B$61,MATCH(E14,'1.2 Niveis Ensino'!$A$2:$A$61,0)),"") | M14: =IFERROR(INDEX(Listas!$H$2:$H$4,MATCH(F14,Listas!$G$2:$G$4,0)),"")
... H61: =IF(A61="","",A61) | I61: =IF(B61="","",B61) | J61: =IF(C61="Sim","true",IF(C61="Não","false","")) | K61: =IFERROR(INDEX('1.1 Modalidades'!$B$2:$B$61,MATCH(D61,'1.1 Modalidades'!$A$2:$A$61,0)),"") | L61: =IFERROR(INDEX('1.2 Niveis Ensino'!$B$2:$B$61,MATCH(E61,'1.2 Niveis Ensino'!$A$2:$A$61,0)),"") | M61: =IFERROR(INDEX(Listas!$H$2:$H$4,MATCH(F61,Listas!$G$2:$G$4,0)),"")

Sheet 2.2 Disciplinas
A1: Nome * | B1: Código * | C1: Carga Horária * | D1: Ativa? * | E1: Categoria da Disciplina | G1: name | H1: externalId | I1: workload | J1: isActive | K1: externalSubjectCategoryId
A2: Programação Orientada a Objetos | B2: DISC-001 | C2: 80 | D2: Sim | E2: Disciplina Normal | G2: =IF(A2="","",A2) -> Programação Orientada a Objetos | H2: =IF(B2="","",B2) -> DISC-001 | I2: =IF(C2="","",C2) -> 80 | J2: =IF(D2="Sim","true",IF(D2="Não","false","")) -> true | K2: =IFERROR(INDEX('1.3 Categorias Disc'!$B$2:$B$61,MATCH(E2,'1.3 Categorias Disc'!$A$2:$A$61,0)),"") -> CAT-001
G3: =IF(A3="","",A3) | H3: =IF(B3="","",B3) | I3: =IF(C3="","",C3) | J3: =IF(D3="Sim","true",IF(D3="Não","false","")) | K3: =IFERROR(INDEX('1.3 Categorias Disc'!$B$2:$B$61,MATCH(E3,'1.3 Categorias Disc'!$A$2:$A$61,0)),"")
G4: =IF(A4="","",A4) | H4: =IF(B4="","",B4) | I4: =IF(C4="","",C4) | J4: =IF(D4="Sim","true",IF(D4="Não","false","")) | K4: =IFERROR(INDEX('1.3 Categorias Disc'!$B$2:$B$61,MATCH(E4,'1.3 Categorias Disc'!$A$2:$A$61,0)),"")
G5: =IF(A5="","",A5) | H5: =IF(B5="","",B5) | I5: =IF(C5="","",C5) | J5: =IF(D5="Sim","true",IF(D5="Não","false","")) | K5: =IFERROR(INDEX('1.3 Categorias Disc'!$B$2:$B$61,MATCH(E5,'1.3 Categorias Disc'!$A$2:$A$61,0)),"")
G6: =IF(A6="","",A6) | H6: =IF(B6="","",B6) | I6: =IF(C6="","",C6) | J6: =IF(D6="Sim","true",IF(D6="Não","false","")) | K6: =IFERROR(INDEX('1.3 Categorias Disc'!$B$2:$B$61,MATCH(E6,'1.3 Categorias Disc'!$A$2:$A$61,0)),"")
G7: =IF(A7="","",A7) | H7: =IF(B7="","",B7) | I7: =IF(C7="","",C7) | J7: =IF(D7="Sim","true",IF(D7="Não","false","")) | K7: =IFERROR(INDEX('1.3 Categorias Disc'!$B$2:$B$61,MATCH(E7,'1.3 Categorias Disc'!$A$2:$A$61,0)),"")
G8: =IF(A8="","",A8) | H8: =IF(B8="","",B8) | I8: =IF(C8="","",C8) | J8: =IF(D8="Sim","true",IF(D8="Não","false","")) | K8: =IFERROR(INDEX('1.3 Categorias Disc'!$B$2:$B$61,MATCH(E8,'1.3 Categorias Disc'!$A$2:$A$61,0)),"")
G9: =IF(A9="","",A9) | H9: =IF(B9="","",B9) | I9: =IF(C9="","",C9) | J9: =IF(D9="Sim","true",IF(D9="Não","false","")) | K9: =IFERROR(INDEX('1.3 Categorias Disc'!$B$2:$B$61,MATCH(E9,'1.3 Categorias Disc'!$A$2:$A$61,0)),"")
G10: =IF(A10="","",A10) | H10: =IF(B10="","",B10) | I10: =IF(C10="","",C10) | J10: =IF(D10="Sim","true",IF(D10="Não","false","")) | K10: =IFERROR(INDEX('1.3 Categorias Disc'!$B$2:$B$61,MATCH(E10,'1.3 Categorias Disc'!$A$2:$A$61,0)),"")
G11: =IF(A11="","",A11) | H11: =IF(B11="","",B11) | I11: =IF(C11="","",C11) | J11: =IF(D11="Sim","true",IF(D11="Não","false","")) | K11: =IFERROR(INDEX('1.3 Categorias Disc'!$B$2:$B$61,MATCH(E11,'1.3 Categorias Disc'!$A$2:$A$61,0)),"")
G12: =IF(A12="","",A12) | H12: =IF(B12="","",B12) | I12: =IF(C12="","",C12) | J12: =IF(D12="Sim","true",IF(D12="Não","false","")) | K12: =IFERROR(INDEX('1.3 Categorias Disc'!$B$2:$B$61,MATCH(E12,'1.3 Categorias Disc'!$A$2:$A$61,0)),"")
G13: =IF(A13="","",A13) | H13: =IF(B13="","",B13) | I13: =IF(C13="","",C13) | J13: =IF(D13="Sim","true",IF(D13="Não","false","")) | K13: =IFERROR(INDEX('1.3 Categorias Disc'!$B$2:$B$61,MATCH(E13,'1.3 Categorias Disc'!$A$2:$A$61,0)),"")
G14: =IF(A14="","",A14) | H14: =IF(B14="","",B14) | I14: =IF(C14="","",C14) | J14: =IF(D14="Sim","true",IF(D14="Não","false","")) | K14: =IFERROR(INDEX('1.3 Categorias Disc'!$B$2:$B$61,MATCH(E14,'1.3 Categorias Disc'!$A$2:$A$61,0)),"")
... G61: =IF(A61="","",A61) | H61: =IF(B61="","",B61) | I61: =IF(C61="","",C61) | J61: =IF(D61="Sim","true",IF(D61="Não","false","")) | K61: =IFERROR(INDEX('1.3 Categorias Disc'!$B$2:$B$61,MATCH(E61,'1.3 Categorias Disc'!$A$2:$A$61,0)),"")

Sheet 2.3 Periodos
A1: Nome * | B1: Código * | C1: Possui Datas Delimitadas? * | D1: Data Início | E1: Data Fim | F1: Ativo? * | G1: Modalidade de Ensino | I1: name | J1: externalId | K1: isTemporal | L1: startDate | M1: endDate | N1: isActive | O1: externalTeachingModalityId
A2: 2026.1 | B2: PER-001 | C2: Sim | D2: 2026-01-01 | E2: 2026-06-30 | F2: Sim | G2: Presencial | I2: =IF(A2="","",A2) -> 2026.1 | J2: =IF(B2="","",B2) -> PER-001 | K2: =IF(C2="Sim","true",IF(C2="Não","false","")) -> true | L2: =IF(D2="","",TEXT(D2,"yyyy-mm-dd")) -> yyyy-01-01 | M2: =IF(E2="","",TEXT(E2,"yyyy-mm-dd")) -> yyyy-06-30 | N2: =IF(F2="Sim","true",IF(F2="Não","false","")) -> true | O2: =IFERROR(INDEX('1.1 Modalidades'!$B$2:$B$61,MATCH(G2,'1.1 Modalidades'!$A$2:$A$61,0)),"") -> MOD-001
I3: =IF(A3="","",A3) | J3: =IF(B3="","",B3) | K3: =IF(C3="Sim","true",IF(C3="Não","false","")) | L3: =IF(D3="","",TEXT(D3,"yyyy-mm-dd")) | M3: =IF(E3="","",TEXT(E3,"yyyy-mm-dd")) | N3: =IF(F3="Sim","true",IF(F3="Não","false","")) | O3: =IFERROR(INDEX('1.1 Modalidades'!$B$2:$B$61,MATCH(G3,'1.1 Modalidades'!$A$2:$A$61,0)),"")
I4: =IF(A4="","",A4) | J4: =IF(B4="","",B4) | K4: =IF(C4="Sim","true",IF(C4="Não","false","")) | L4: =IF(D4="","",TEXT(D4,"yyyy-mm-dd")) | M4: =IF(E4="","",TEXT(E4,"yyyy-mm-dd")) | N4: =IF(F4="Sim","true",IF(F4="Não","false","")) | O4: =IFERROR(INDEX('1.1 Modalidades'!$B$2:$B$61,MATCH(G4,'1.1 Modalidades'!$A$2:$A$61,0)),"")
I5: =IF(A5="","",A5) | J5: =IF(B5="","",B5) | K5: =IF(C5="Sim","true",IF(C5="Não","false","")) | L5: =IF(D5="","",TEXT(D5,"yyyy-mm-dd")) | M5: =IF(E5="","",TEXT(E5,"yyyy-mm-dd")) | N5: =IF(F5="Sim","true",IF(F5="Não","false","")) | O5: =IFERROR(INDEX('1.1 Modalidades'!$B$2:$B$61,MATCH(G5,'1.1 Modalidades'!$A$2:$A$61,0)),"")
I6: =IF(A6="","",A6) | J6: =IF(B6="","",B6) | K6: =IF(C6="Sim","true",IF(C6="Não","false","")) | L6: =IF(D6="","",TEXT(D6,"yyyy-mm-dd")) | M6: =IF(E6="","",TEXT(E6,"yyyy-mm-dd")) | N6: =IF(F6="Sim","true",IF(F6="Não","false","")) | O6: =IFERROR(INDEX('1.1 Modalidades'!$B$2:$B$61,MATCH(G6,'1.1 Modalidades'!$A$2:$A$61,0)),"")
I7: =IF(A7="","",A7) | J7: =IF(B7="","",B7) | K7: =IF(C7="Sim","true",IF(C7="Não","false","")) | L7: =IF(D7="","",TEXT(D7,"yyyy-mm-dd")) | M7: =IF(E7="","",TEXT(E7,"yyyy-mm-dd")) | N7: =IF(F7="Sim","true",IF(F7="Não","false","")) | O7: =IFERROR(INDEX('1.1 Modalidades'!$B$2:$B$61,MATCH(G7,'1.1 Modalidades'!$A$2:$A$61,0)),"")
I8: =IF(A8="","",A8) | J8: =IF(B8="","",B8) | K8: =IF(C8="Sim","true",IF(C8="Não","false","")) | L8: =IF(D8="","",TEXT(D8,"yyyy-mm-dd")) | M8: =IF(E8="","",TEXT(E8,"yyyy-mm-dd")) | N8: =IF(F8="Sim","true",IF(F8="Não","false","")) | O8: =IFERROR(INDEX('1.1 Modalidades'!$B$2:$B$61,MATCH(G8,'1.1 Modalidades'!$A$2:$A$61,0)),"")
I9: =IF(A9="","",A9) | J9: =IF(B9="","",B9) | K9: =IF(C9="Sim","true",IF(C9="Não","false","")) | L9: =IF(D9="","",TEXT(D9,"yyyy-mm-dd")) | M9: =IF(E9="","",TEXT(E9,"yyyy-mm-dd")) | N9: =IF(F9="Sim","true",IF(F9="Não","false","")) | O9: =IFERROR(INDEX('1.1 Modalidades'!$B$2:$B$61,MATCH(G9,'1.1 Modalidades'!$A$2:$A$61,0)),"")
I10: =IF(A10="","",A10) | J10: =IF(B10="","",B10) | K10: =IF(C10="Sim","true",IF(C10="Não","false","")) | L10: =IF(D10="","",TEXT(D10,"yyyy-mm-dd")) | M10: =IF(E10="","",TEXT(E10,"yyyy-mm-dd")) | N10: =IF(F10="Sim","true",IF(F10="Não","false","")) | O10: =IFERROR(INDEX('1.1 Modalidades'!$B$2:$B$61,MATCH(G10,'1.1 Modalidades'!$A$2:$A$61,0)),"")
I11: =IF(A11="","",A11) | J11: =IF(B11="","",B11) | K11: =IF(C11="Sim","true",IF(C11="Não","false","")) | L11: =IF(D11="","",TEXT(D11,"yyyy-mm-dd")) | M11: =IF(E11="","",TEXT(E11,"yyyy-mm-dd")) | N11: =IF(F11="Sim","true",IF(F11="Não","false","")) | O11: =IFERROR(INDEX('1.1 Modalidades'!$B$2:$B$61,MATCH(G11,'1.1 Modalidades'!$A$2:$A$61,0)),"")
I12: =IF(A12="","",A12) | J12: =IF(B12="","",B12) | K12: =IF(C12="Sim","true",IF(C12="Não","false","")) | L12: =IF(D12="","",TEXT(D12,"yyyy-mm-dd")) | M12: =IF(E12="","",TEXT(E12,"yyyy-mm-dd")) | N12: =IF(F12="Sim","true",IF(F12="Não","false","")) | O12: =IFERROR(INDEX('1.1 Modalidades'!$B$2:$B$61,MATCH(G12,'1.1 Modalidades'!$A$2:$A$61,0)),"")
I13: =IF(A13="","",A13) | J13: =IF(B13="","",B13) | K13: =IF(C13="Sim","true",IF(C13="Não","false","")) | L13: =IF(D13="","",TEXT(D13,"yyyy-mm-dd")) | M13: =IF(E13="","",TEXT(E13,"yyyy-mm-dd")) | N13: =IF(F13="Sim","true",IF(F13="Não","false","")) | O13: =IFERROR(INDEX('1.1 Modalidades'!$B$2:$B$61,MATCH(G13,'1.1 Modalidades'!$A$2:$A$61,0)),"")
I14: =IF(A14="","",A14) | J14: =IF(B14="","",B14) | K14: =IF(C14="Sim","true",IF(C14="Não","false","")) | L14: =IF(D14="","",TEXT(D14,"yyyy-mm-dd")) | M14: =IF(E14="","",TEXT(E14,"yyyy-mm-dd")) | N14: =IF(F14="Sim","true",IF(F14="Não","false","")) | O14: =IFERROR(INDEX('1.1 Modalidades'!$B$2:$B$61,MATCH(G14,'1.1 Modalidades'!$A$2:$A$61,0)),"")
... I61: =IF(A61="","",A61) | J61: =IF(B61="","",B61) | K61: =IF(C61="Sim","true",IF(C61="Não","false","")) | L61: =IF(D61="","",TEXT(D61,"yyyy-mm-dd")) | M61: =IF(E61="","",TEXT(E61,"yyyy-mm-dd")) | N61: =IF(F61="Sim","true",IF(F61="Não","false","")) | O61: =IFERROR(INDEX('1.1 Modalidades'!$B$2:$B$61,MATCH(G61,'1.1 Modalidades'!$A$2:$A$61,0)),"")

Sheet 2.4 Curriculos
A1: Curso * | B1: Nome * | C1: Código * | D1: Carga Horária * | E1: Vigência Início | F1: Vigência Fim | G1: Ativo? | I1: externalCourseId | J1: name | K1: externalId | L1: workload | M1: startDate | N1: endDate | O1: isActive
A2: Administração | B2: Currículo Administração | C2: CR-001 | D2: 3000 | E2: 2026-01-01 | G2: Sim | I2: =IFERROR(INDEX('2.1 Cursos'!$B$2:$B$61,MATCH(A2,'2.1 Cursos'!$A$2:$A$61,0)),"") -> CUR-001 | J2: =IF(B2="","",B2) -> Currículo Administração | K2: =IF(C2="","",C2) -> CR-001 | L2: =IF(D2="","",D2) -> 3000 | M2: =IF(E2="","",TEXT(E2,"yyyy-mm-dd")) -> yyyy-01-01 | N2: =IF(F2="","",TEXT(F2,"yyyy-mm-dd")) | O2: =IF(G2="Sim","true",IF(G2="Não","false","")) -> true
I3: =IFERROR(INDEX('2.1 Cursos'!$B$2:$B$61,MATCH(A3,'2.1 Cursos'!$A$2:$A$61,0)),"") | J3: =IF(B3="","",B3) | K3: =IF(C3="","",C3) | L3: =IF(D3="","",D3) | M3: =IF(E3="","",TEXT(E3,"yyyy-mm-dd")) | N3: =IF(F3="","",TEXT(F3,"yyyy-mm-dd")) | O3: =IF(G3="Sim","true",IF(G3="Não","false",""))
I4: =IFERROR(INDEX('2.1 Cursos'!$B$2:$B$61,MATCH(A4,'2.1 Cursos'!$A$2:$A$61,0)),"") | J4: =IF(B4="","",B4) | K4: =IF(C4="","",C4) | L4: =IF(D4="","",D4) | M4: =IF(E4="","",TEXT(E4,"yyyy-mm-dd")) | N4: =IF(F4="","",TEXT(F4,"yyyy-mm-dd")) | O4: =IF(G4="Sim","true",IF(G4="Não","false",""))
I5: =IFERROR(INDEX('2.1 Cursos'!$B$2:$B$61,MATCH(A5,'2.1 Cursos'!$A$2:$A$61,0)),"") | J5: =IF(B5="","",B5) | K5: =IF(C5="","",C5) | L5: =IF(D5="","",D5) | M5: =IF(E5="","",TEXT(E5,"yyyy-mm-dd")) | N5: =IF(F5="","",TEXT(F5,"yyyy-mm-dd")) | O5: =IF(G5="Sim","true",IF(G5="Não","false",""))
I6: =IFERROR(INDEX('2.1 Cursos'!$B$2:$B$61,MATCH(A6,'2.1 Cursos'!$A$2:$A$61,0)),"") | J6: =IF(B6="","",B6) | K6: =IF(C6="","",C6) | L6: =IF(D6="","",D6) | M6: =IF(E6="","",TEXT(E6,"yyyy-mm-dd")) | N6: =IF(F6="","",TEXT(F6,"yyyy-mm-dd")) | O6: =IF(G6="Sim","true",IF(G6="Não","false",""))
I7: =IFERROR(INDEX('2.1 Cursos'!$B$2:$B$61,MATCH(A7,'2.1 Cursos'!$A$2:$A$61,0)),"") | J7: =IF(B7="","",B7) | K7: =IF(C7="","",C7) | L7: =IF(D7="","",D7) | M7: =IF(E7="","",TEXT(E7,"yyyy-mm-dd")) | N7: =IF(F7="","",TEXT(F7,"yyyy-mm-dd")) | O7: =IF(G7="Sim","true",IF(G7="Não","false",""))
I8: =IFERROR(INDEX('2.1 Cursos'!$B$2:$B$61,MATCH(A8,'2.1 Cursos'!$A$2:$A$61,0)),"") | J8: =IF(B8="","",B8) | K8: =IF(C8="","",C8) | L8: =IF(D8="","",D8) | M8: =IF(E8="","",TEXT(E8,"yyyy-mm-dd")) | N8: =IF(F8="","",TEXT(F8,"yyyy-mm-dd")) | O8: =IF(G8="Sim","true",IF(G8="Não","false",""))
I9: =IFERROR(INDEX('2.1 Cursos'!$B$2:$B$61,MATCH(A9,'2.1 Cursos'!$A$2:$A$61,0)),"") | J9: =IF(B9="","",B9) | K9: =IF(C9="","",C9) | L9: =IF(D9="","",D9) | M9: =IF(E9="","",TEXT(E9,"yyyy-mm-dd")) | N9: =IF(F9="","",TEXT(F9,"yyyy-mm-dd")) | O9: =IF(G9="Sim","true",IF(G9="Não","false",""))
I10: =IFERROR(INDEX('2.1 Cursos'!$B$2:$B$61,MATCH(A10,'2.1 Cursos'!$A$2:$A$61,0)),"") | J10: =IF(B10="","",B10) | K10: =IF(C10="","",C10) | L10: =IF(D10="","",D10) | M10: =IF(E10="","",TEXT(E10,"yyyy-mm-dd")) | N10: =IF(F10="","",TEXT(F10,"yyyy-mm-dd")) | O10: =IF(G10="Sim","true",IF(G10="Não","false",""))
I11: =IFERROR(INDEX('2.1 Cursos'!$B$2:$B$61,MATCH(A11,'2.1 Cursos'!$A$2:$A$61,0)),"") | J11: =IF(B11="","",B11) | K11: =IF(C11="","",C11) | L11: =IF(D11="","",D11) | M11: =IF(E11="","",TEXT(E11,"yyyy-mm-dd")) | N11: =IF(F11="","",TEXT(F11,"yyyy-mm-dd")) | O11: =IF(G11="Sim","true",IF(G11="Não","false",""))
I12: =IFERROR(INDEX('2.1 Cursos'!$B$2:$B$61,MATCH(A12,'2.1 Cursos'!$A$2:$A$61,0)),"") | J12: =IF(B12="","",B12) | K12: =IF(C12="","",C12) | L12: =IF(D12="","",D12) | M12: =IF(E12="","",TEXT(E12,"yyyy-mm-dd")) | N12: =IF(F12="","",TEXT(F12,"yyyy-mm-dd")) | O12: =IF(G12="Sim","true",IF(G12="Não","false",""))
I13: =IFERROR(INDEX('2.1 Cursos'!$B$2:$B$61,MATCH(A13,'2.1 Cursos'!$A$2:$A$61,0)),"") | J13: =IF(B13="","",B13) | K13: =IF(C13="","",C13) | L13: =IF(D13="","",D13) | M13: =IF(E13="","",TEXT(E13,"yyyy-mm-dd")) | N13: =IF(F13="","",TEXT(F13,"yyyy-mm-dd")) | O13: =IF(G13="Sim","true",IF(G13="Não","false",""))
I14: =IFERROR(INDEX('2.1 Cursos'!$B$2:$B$61,MATCH(A14,'2.1 Cursos'!$A$2:$A$61,0)),"") | J14: =IF(B14="","",B14) | K14: =IF(C14="","",C14) | L14: =IF(D14="","",D14) | M14: =IF(E14="","",TEXT(E14,"yyyy-mm-dd")) | N14: =IF(F14="","",TEXT(F14,"yyyy-mm-dd")) | O14: =IF(G14="Sim","true",IF(G14="Não","false",""))
... I61: =IFERROR(INDEX('2.1 Cursos'!$B$2:$B$61,MATCH(A61,'2.1 Cursos'!$A$2:$A$61,0)),"") | J61: =IF(B61="","",B61) | K61: =IF(C61="","",C61) | L61: =IF(D61="","",D61) | M61: =IF(E61="","",TEXT(E61,"yyyy-mm-dd")) | N61: =IF(F61="","",TEXT(F61,"yyyy-mm-dd")) | O61: =IF(G61="Sim","true",IF(G61="Não","false",""))

Sheet 2.5 Disc Curriculos
A1: Curso * | B1: Currículo * | C1: Disciplina * | D1: Tipo da Disciplina * | E1: Grupo | F1: Subgrupo | H1: externalCourseId | I1: externalCurriculumId | J1: externalSubjectId | K1: subjectTypeId | L1: group | M1: subgroup
A2: Administração | B2: Currículo Administração | C2: Programação Orientada a Objetos | D2: Obrigatória | E2: 1 | F2: 1 | H2: =IFERROR(INDEX('2.1 Cursos'!$B$2:$B$61,MATCH(A2,'2.1 Cursos'!$A$2:$A$61,0)),"") -> CUR-001 | I2: =IFERROR(INDEX('2.4 Curriculos'!$C$2:$C$61,MATCH(B2,'2.4 Curriculos'!$B$2:$B$61,0)),"") -> CR-001 | J2: =IFERROR(INDEX('2.2 Disciplinas'!$B$2:$B$61,MATCH(C2,'2.2 Disciplinas'!$A$2:$A$61,0)),"") -> DISC-001 | K2: =IFERROR(INDEX(Listas!$N$2:$N$4,MATCH(D2,Listas!$M$2:$M$4,0)),"") -> compulsory | L2: =IF(E2="","",E2) -> 1 | M2: =IF(F2="","",F2) -> 1
H3: =IFERROR(INDEX('2.1 Cursos'!$B$2:$B$61,MATCH(A3,'2.1 Cursos'!$A$2:$A$61,0)),"") | I3: =IFERROR(INDEX('2.4 Curriculos'!$C$2:$C$61,MATCH(B3,'2.4 Curriculos'!$B$2:$B$61,0)),"") | J3: =IFERROR(INDEX('2.2 Disciplinas'!$B$2:$B$61,MATCH(C3,'2.2 Disciplinas'!$A$2:$A$61,0)),"") | K3: =IFERROR(INDEX(Listas!$N$2:$N$4,MATCH(D3,Listas!$M$2:$M$4,0)),"") | L3: =IF(E3="","",E3) | M3: =IF(F3="","",F3)
H4: =IFERROR(INDEX('2.1 Cursos'!$B$2:$B$61,MATCH(A4,'2.1 Cursos'!$A$2:$A$61,0)),"") | I4: =IFERROR(INDEX('2.4 Curriculos'!$C$2:$C$61,MATCH(B4,'2.4 Curriculos'!$B$2:$B$61,0)),"") | J4: =IFERROR(INDEX('2.2 Disciplinas'!$B$2:$B$61,MATCH(C4,'2.2 Disciplinas'!$A$2:$A$61,0)),"") | K4: =IFERROR(INDEX(Listas!$N$2:$N$4,MATCH(D4,Listas!$M$2:$M$4,0)),"") | L4: =IF(E4="","",E4) | M4: =IF(F4="","",F4)
H5: =IFERROR(INDEX('2.1 Cursos'!$B$2:$B$61,MATCH(A5,'2.1 Cursos'!$A$2:$A$61,0)),"") | I5: =IFERROR(INDEX('2.4 Curriculos'!$C$2:$C$61,MATCH(B5,'2.4 Curriculos'!$B$2:$B$61,0)),"") | J5: =IFERROR(INDEX('2.2 Disciplinas'!$B$2:$B$61,MATCH(C5,'2.2 Disciplinas'!$A$2:$A$61,0)),"") | K5: =IFERROR(INDEX(Listas!$N$2:$N$4,MATCH(D5,Listas!$M$2:$M$4,0)),"") | L5: =IF(E5="","",E5) | M5: =IF(F5="","",F5)
H6: =IFERROR(INDEX('2.1 Cursos'!$B$2:$B$61,MATCH(A6,'2.1 Cursos'!$A$2:$A$61,0)),"") | I6: =IFERROR(INDEX('2.4 Curriculos'!$C$2:$C$61,MATCH(B6,'2.4 Curriculos'!$B$2:$B$61,0)),"") | J6: =IFERROR(INDEX('2.2 Disciplinas'!$B$2:$B$61,MATCH(C6,'2.2 Disciplinas'!$A$2:$A$61,0)),"") | K6: =IFERROR(INDEX(Listas!$N$2:$N$4,MATCH(D6,Listas!$M$2:$M$4,0)),"") | L6: =IF(E6="","",E6) | M6: =IF(F6="","",F6)
H7: =IFERROR(INDEX('2.1 Cursos'!$B$2:$B$61,MATCH(A7,'2.1 Cursos'!$A$2:$A$61,0)),"") | I7: =IFERROR(INDEX('2.4 Curriculos'!$C$2:$C$61,MATCH(B7,'2.4 Curriculos'!$B$2:$B$61,0)),"") | J7: =IFERROR(INDEX('2.2 Disciplinas'!$B$2:$B$61,MATCH(C7,'2.2 Disciplinas'!$A$2:$A$61,0)),"") | K7: =IFERROR(INDEX(Listas!$N$2:$N$4,MATCH(D7,Listas!$M$2:$M$4,0)),"") | L7: =IF(E7="","",E7) | M7: =IF(F7="","",F7)
H8: =IFERROR(INDEX('2.1 Cursos'!$B$2:$B$61,MATCH(A8,'2.1 Cursos'!$A$2:$A$61,0)),"") | I8: =IFERROR(INDEX('2.4 Curriculos'!$C$2:$C$61,MATCH(B8,'2.4 Curriculos'!$B$2:$B$61,0)),"") | J8: =IFERROR(INDEX('2.2 Disciplinas'!$B$2:$B$61,MATCH(C8,'2.2 Disciplinas'!$A$2:$A$61,0)),"") | K8: =IFERROR(INDEX(Listas!$N$2:$N$4,MATCH(D8,Listas!$M$2:$M$4,0)),"") | L8: =IF(E8="","",E8) | M8: =IF(F8="","",F8)
H9: =IFERROR(INDEX('2.1 Cursos'!$B$2:$B$61,MATCH(A9,'2.1 Cursos'!$A$2:$A$61,0)),"") | I9: =IFERROR(INDEX('2.4 Curriculos'!$C$2:$C$61,MATCH(B9,'2.4 Curriculos'!$B$2:$B$61,0)),"") | J9: =IFERROR(INDEX('2.2 Disciplinas'!$B$2:$B$61,MATCH(C9,'2.2 Disciplinas'!$A$2:$A$61,0)),"") | K9: =IFERROR(INDEX(Listas!$N$2:$N$4,MATCH(D9,Listas!$M$2:$M$4,0)),"") | L9: =IF(E9="","",E9) | M9: =IF(F9="","",F9)
H10: =IFERROR(INDEX('2.1 Cursos'!$B$2:$B$61,MATCH(A10,'2.1 Cursos'!$A$2:$A$61,0)),"") | I10: =IFERROR(INDEX('2.4 Curriculos'!$C$2:$C$61,MATCH(B10,'2.4 Curriculos'!$B$2:$B$61,0)),"") | J10: =IFERROR(INDEX('2.2 Disciplinas'!$B$2:$B$61,MATCH(C10,'2.2 Disciplinas'!$A$2:$A$61,0)),"") | K10: =IFERROR(INDEX(Listas!$N$2:$N$4,MATCH(D10,Listas!$M$2:$M$4,0)),"") | L10: =IF(E10="","",E10) | M10: =IF(F10="","",F10)
H11: =IFERROR(INDEX('2.1 Cursos'!$B$2:$B$61,MATCH(A11,'2.1 Cursos'!$A$2:$A$61,0)),"") | I11: =IFERROR(INDEX('2.4 Curriculos'!$C$2:$C$61,MATCH(B11,'2.4 Curriculos'!$B$2:$B$61,0)),"") | J11: =IFERROR(INDEX('2.2 Disciplinas'!$B$2:$B$61,MATCH(C11,'2.2 Disciplinas'!$A$2:$A$61,0)),"") | K11: =IFERROR(INDEX(Listas!$N$2:$N$4,MATCH(D11,Listas!$M$2:$M$4,0)),"") | L11: =IF(E11="","",E11) | M11: =IF(F11="","",F11)
H12: =IFERROR(INDEX('2.1 Cursos'!$B$2:$B$61,MATCH(A12,'2.1 Cursos'!$A$2:$A$61,0)),"") | I12: =IFERROR(INDEX('2.4 Curriculos'!$C$2:$C$61,MATCH(B12,'2.4 Curriculos'!$B$2:$B$61,0)),"") | J12: =IFERROR(INDEX('2.2 Disciplinas'!$B$2:$B$61,MATCH(C12,'2.2 Disciplinas'!$A$2:$A$61,0)),"") | K12: =IFERROR(INDEX(Listas!$N$2:$N$4,MATCH(D12,Listas!$M$2:$M$4,0)),"") | L12: =IF(E12="","",E12) | M12: =IF(F12="","",F12)
H13: =IFERROR(INDEX('2.1 Cursos'!$B$2:$B$61,MATCH(A13,'2.1 Cursos'!$A$2:$A$61,0)),"") | I13: =IFERROR(INDEX('2.4 Curriculos'!$C$2:$C$61,MATCH(B13,'2.4 Curriculos'!$B$2:$B$61,0)),"") | J13: =IFERROR(INDEX('2.2 Disciplinas'!$B$2:$B$61,MATCH(C13,'2.2 Disciplinas'!$A$2:$A$61,0)),"") | K13: =IFERROR(INDEX(Listas!$N$2:$N$4,MATCH(D13,Listas!$M$2:$M$4,0)),"") | L13: =IF(E13="","",E13) | M13: =IF(F13="","",F13)
H14: =IFERROR(INDEX('2.1 Cursos'!$B$2:$B$61,MATCH(A14,'2.1 Cursos'!$A$2:$A$61,0)),"") | I14: =IFERROR(INDEX('2.4 Curriculos'!$C$2:$C$61,MATCH(B14,'2.4 Curriculos'!$B$2:$B$61,0)),"") | J14: =IFERROR(INDEX('2.2 Disciplinas'!$B$2:$B$61,MATCH(C14,'2.2 Disciplinas'!$A$2:$A$61,0)),"") | K14: =IFERROR(INDEX(Listas!$N$2:$N$4,MATCH(D14,Listas!$M$2:$M$4,0)),"") | L14: =IF(E14="","",E14) | M14: =IF(F14="","",F14)
... H61: =IFERROR(INDEX('2.1 Cursos'!$B$2:$B$61,MATCH(A61,'2.1 Cursos'!$A$2:$A$61,0)),"") | I61: =IFERROR(INDEX('2.4 Curriculos'!$C$2:$C$61,MATCH(B61,'2.4 Curriculos'!$B$2:$B$61,0)),"") | J61: =IFERROR(INDEX('2.2 Disciplinas'!$B$2:$B$61,MATCH(C61,'2.2 Disciplinas'!$A$2:$A$61,0)),"") | K61: =IFERROR(INDEX(Listas!$N$2:$N$4,MATCH(D61,Listas!$M$2:$M$4,0)),"") | L61: =IF(E61="","",E61) | M61: =IF(F61="","",F61)

Sheet 2.6 Turmas Disc
A1: Turma * | B1: Disciplina * | C1: Currículo * | D1: Curso * | E1: Período | F1: Turno | G1: Data Início | H1: Data Fim | I1: Código * | J1: Ativa? | K1: É Gerencial? | L1: Turma/Disc. Gerencial Vinculada | M1: Tipo de Gerenciamento | N1: Integra com GPA? | O1: Integra com NPJ? | P1: É Comunidade LXP? | R1: externalClassId | S1: externalSubjectId | T1: externalCurriculumId | U1: externalCourseId | V1: externalPeriodId | W1: externalShiftId | X1: startDate | Y1: endDate | Z1: externalId | AA1: isActive | AB1: isManagerial | AC1: parentExternalClassSubjectId | AD1: managementType | AE1: ext.gpa.shouldIntegrate | AF1: ext.npj.shouldIntegrate | AG1: ext.lxp.isCommunity
A2: Turma A | B2: Programação Orientada a Objetos | C2: Currículo Administração | D2: Administração | E2: 2026.1 | F2: Manhã | G2: 2026-01-01 | H2: 2026-06-30 | I2: TURDISC-001 | J2: Sim | K2: Não | M2: Mestre | P2: Não | R2: =IFERROR(INDEX('1.11 Turmas'!$B$2:$B$61,MATCH(A2,'1.11 Turmas'!$A$2:$A$61,0)),"") -> TURMA-001 | S2: =IFERROR(INDEX('2.2 Disciplinas'!$B$2:$B$61,MATCH(B2,'2.2 Disciplinas'!$A$2:$A$61,0)),"") -> DISC-001 | T2: =IFERROR(INDEX('2.4 Curriculos'!$C$2:$C$61,MATCH(C2,'2.4 Curriculos'!$B$2:$B$61,0)),"") -> CR-001 | U2: =IFERROR(INDEX('2.1 Cursos'!$B$2:$B$61,MATCH(D2,'2.1 Cursos'!$A$2:$A$61,0)),"") -> CUR-001 | V2: =IFERROR(INDEX('2.3 Periodos'!$B$2:$B$61,MATCH(E2,'2.3 Periodos'!$A$2:$A$61,0)),"") -> PER-001 | W2: =IFERROR(INDEX('1.4 Turnos'!$B$2:$B$61,MATCH(F2,'1.4 Turnos'!$A$2:$A$61,0)),"") -> TUR-001 | X2: =IF(G2="","",TEXT(G2,"yyyy-mm-dd")) -> yyyy-01-01 | Y2: =IF(H2="","",TEXT(H2,"yyyy-mm-dd")) -> yyyy-06-30 | Z2: =IF(I2="","",I2) -> TURDISC-001 | AA2: =IF(J2="Sim","true",IF(J2="Não","false","")) -> true | AB2: =IF(K2="Sim","true",IF(K2="Não","false","")) -> false | AC2: =IF(L2="","",L2) | AD2: =IFERROR(INDEX(Listas!$Z$2:$Z$3,MATCH(M2,Listas!$Y$2:$Y$3,0)),"") -> master | AE2: =IF(N2="Sim","true",IF(N2="Não","false","")) | AF2: =IF(O2="Sim","true",IF(O2="Não","false","")) | AG2: =IF(P2="Sim","true",IF(P2="Não","false","")) -> false
R3: =IFERROR(INDEX('1.11 Turmas'!$B$2:$B$61,MATCH(A3,'1.11 Turmas'!$A$2:$A$61,0)),"") | S3: =IFERROR(INDEX('2.2 Disciplinas'!$B$2:$B$61,MATCH(B3,'2.2 Disciplinas'!$A$2:$A$61,0)),"") | T3: =IFERROR(INDEX('2.4 Curriculos'!$C$2:$C$61,MATCH(C3,'2.4 Curriculos'!$B$2:$B$61,0)),"") | U3: =IFERROR(INDEX('2.1 Cursos'!$B$2:$B$61,MATCH(D3,'2.1 Cursos'!$A$2:$A$61,0)),"") | V3: =IFERROR(INDEX('2.3 Periodos'!$B$2:$B$61,MATCH(E3,'2.3 Periodos'!$A$2:$A$61,0)),"") | W3: =IFERROR(INDEX('1.4 Turnos'!$B$2:$B$61,MATCH(F3,'1.4 Turnos'!$A$2:$A$61,0)),"") | X3: =IF(G3="","",TEXT(G3,"yyyy-mm-dd")) | Y3: =IF(H3="","",TEXT(H3,"yyyy-mm-dd")) | Z3: =IF(I3="","",I3) | AA3: =IF(J3="Sim","true",IF(J3="Não","false","")) | AB3: =IF(K3="Sim","true",IF(K3="Não","false","")) | AC3: =IF(L3="","",L3) | AD3: =IFERROR(INDEX(Listas!$Z$2:$Z$3,MATCH(M3,Listas!$Y$2:$Y$3,0)),"") | AE3: =IF(N3="Sim","true",IF(N3="Não","false","")) | AF3: =IF(O3="Sim","true",IF(O3="Não","false","")) | AG3: =IF(P3="Sim","true",IF(P3="Não","false",""))
R4: =IFERROR(INDEX('1.11 Turmas'!$B$2:$B$61,MATCH(A4,'1.11 Turmas'!$A$2:$A$61,0)),"") | S4: =IFERROR(INDEX('2.2 Disciplinas'!$B$2:$B$61,MATCH(B4,'2.2 Disciplinas'!$A$2:$A$61,0)),"") | T4: =IFERROR(INDEX('2.4 Curriculos'!$C$2:$C$61,MATCH(C4,'2.4 Curriculos'!$B$2:$B$61,0)),"") | U4: =IFERROR(INDEX('2.1 Cursos'!$B$2:$B$61,MATCH(D4,'2.1 Cursos'!$A$2:$A$61,0)),"") | V4: =IFERROR(INDEX('2.3 Periodos'!$B$2:$B$61,MATCH(E4,'2.3 Periodos'!$A$2:$A$61,0)),"") | W4: =IFERROR(INDEX('1.4 Turnos'!$B$2:$B$61,MATCH(F4,'1.4 Turnos'!$A$2:$A$61,0)),"") | X4: =IF(G4="","",TEXT(G4,"yyyy-mm-dd")) | Y4: =IF(H4="","",TEXT(H4,"yyyy-mm-dd")) | Z4: =IF(I4="","",I4) | AA4: =IF(J4="Sim","true",IF(J4="Não","false","")) | AB4: =IF(K4="Sim","true",IF(K4="Não","false","")) | AC4: =IF(L4="","",L4) | AD4: =IFERROR(INDEX(Listas!$Z$2:$Z$3,MATCH(M4,Listas!$Y$2:$Y$3,0)),"") | AE4: =IF(N4="Sim","true",IF(N4="Não","false","")) | AF4: =IF(O4="Sim","true",IF(O4="Não","false","")) | AG4: =IF(P4="Sim","true",IF(P4="Não","false",""))
R5: =IFERROR(INDEX('1.11 Turmas'!$B$2:$B$61,MATCH(A5,'1.11 Turmas'!$A$2:$A$61,0)),"") | S5: =IFERROR(INDEX('2.2 Disciplinas'!$B$2:$B$61,MATCH(B5,'2.2 Disciplinas'!$A$2:$A$61,0)),"") | T5: =IFERROR(INDEX('2.4 Curriculos'!$C$2:$C$61,MATCH(C5,'2.4 Curriculos'!$B$2:$B$61,0)),"") | U5: =IFERROR(INDEX('2.1 Cursos'!$B$2:$B$61,MATCH(D5,'2.1 Cursos'!$A$2:$A$61,0)),"") | V5: =IFERROR(INDEX('2.3 Periodos'!$B$2:$B$61,MATCH(E5,'2.3 Periodos'!$A$2:$A$61,0)),"") | W5: =IFERROR(INDEX('1.4 Turnos'!$B$2:$B$61,MATCH(F5,'1.4 Turnos'!$A$2:$A$61,0)),"") | X5: =IF(G5="","",TEXT(G5,"yyyy-mm-dd")) | Y5: =IF(H5="","",TEXT(H5,"yyyy-mm-dd")) | Z5: =IF(I5="","",I5) | AA5: =IF(J5="Sim","true",IF(J5="Não","false","")) | AB5: =IF(K5="Sim","true",IF(K5="Não","false","")) | AC5: =IF(L5="","",L5) | AD5: =IFERROR(INDEX(Listas!$Z$2:$Z$3,MATCH(M5,Listas!$Y$2:$Y$3,0)),"") | AE5: =IF(N5="Sim","true",IF(N5="Não","false","")) | AF5: =IF(O5="Sim","true",IF(O5="Não","false","")) | AG5: =IF(P5="Sim","true",IF(P5="Não","false",""))
R6: =IFERROR(INDEX('1.11 Turmas'!$B$2:$B$61,MATCH(A6,'1.11 Turmas'!$A$2:$A$61,0)),"") | S6: =IFERROR(INDEX('2.2 Disciplinas'!$B$2:$B$61,MATCH(B6,'2.2 Disciplinas'!$A$2:$A$61,0)),"") | T6: =IFERROR(INDEX('2.4 Curriculos'!$C$2:$C$61,MATCH(C6,'2.4 Curriculos'!$B$2:$B$61,0)),"") | U6: =IFERROR(INDEX('2.1 Cursos'!$B$2:$B$61,MATCH(D6,'2.1 Cursos'!$A$2:$A$61,0)),"") | V6: =IFERROR(INDEX('2.3 Periodos'!$B$2:$B$61,MATCH(E6,'2.3 Periodos'!$A$2:$A$61,0)),"") | W6: =IFERROR(INDEX('1.4 Turnos'!$B$2:$B$61,MATCH(F6,'1.4 Turnos'!$A$2:$A$61,0)),"") | X6: =IF(G6="","",TEXT(G6,"yyyy-mm-dd")) | Y6: =IF(H6="","",TEXT(H6,"yyyy-mm-dd")) | Z6: =IF(I6="","",I6) | AA6: =IF(J6="Sim","true",IF(J6="Não","false","")) | AB6: =IF(K6="Sim","true",IF(K6="Não","false","")) | AC6: =IF(L6="","",L6) | AD6: =IFERROR(INDEX(Listas!$Z$2:$Z$3,MATCH(M6,Listas!$Y$2:$Y$3,0)),"") | AE6: =IF(N6="Sim","true",IF(N6="Não","false","")) | AF6: =IF(O6="Sim","true",IF(O6="Não","false","")) | AG6: =IF(P6="Sim","true",IF(P6="Não","false",""))
R7: =IFERROR(INDEX('1.11 Turmas'!$B$2:$B$61,MATCH(A7,'1.11 Turmas'!$A$2:$A$61,0)),"") | S7: =IFERROR(INDEX('2.2 Disciplinas'!$B$2:$B$61,MATCH(B7,'2.2 Disciplinas'!$A$2:$A$61,0)),"") | T7: =IFERROR(INDEX('2.4 Curriculos'!$C$2:$C$61,MATCH(C7,'2.4 Curriculos'!$B$2:$B$61,0)),"") | U7: =IFERROR(INDEX('2.1 Cursos'!$B$2:$B$61,MATCH(D7,'2.1 Cursos'!$A$2:$A$61,0)),"") | V7: =IFERROR(INDEX('2.3 Periodos'!$B$2:$B$61,MATCH(E7,'2.3 Periodos'!$A$2:$A$61,0)),"") | W7: =IFERROR(INDEX('1.4 Turnos'!$B$2:$B$61,MATCH(F7,'1.4 Turnos'!$A$2:$A$61,0)),"") | X7: =IF(G7="","",TEXT(G7,"yyyy-mm-dd")) | Y7: =IF(H7="","",TEXT(H7,"yyyy-mm-dd")) | Z7: =IF(I7="","",I7) | AA7: =IF(J7="Sim","true",IF(J7="Não","false","")) | AB7: =IF(K7="Sim","true",IF(K7="Não","false","")) | AC7: =IF(L7="","",L7) | AD7: =IFERROR(INDEX(Listas!$Z$2:$Z$3,MATCH(M7,Listas!$Y$2:$Y$3,0)),"") | AE7: =IF(N7="Sim","true",IF(N7="Não","false","")) | AF7: =IF(O7="Sim","true",IF(O7="Não","false","")) | AG7: =IF(P7="Sim","true",IF(P7="Não","false",""))
